Workbook

Sheet transaction
A1: Account Holder: | B1: SASA PAY
A2: Short Code: | B2: 756756
A3: Account: | B3: MMF Account for Organization
A4: Time Period: | B4: From | C4: 02-09-2026 00:00:00 | D4: To | E4: 02-09-2026 23:59:59
A5: Operator: | B5: Muthoni | C5: Organization: | D5: SASA PAY | E5: Date of Report: | F5: 10-09-2026 11:42:06
A6: Opening Balance: | B6: 28661758 | C6: Closing Balance: | D6: 8341383.6 | E6: Available Balance: | G6: Total Paid In: | H6: 18632763 | I6: Total Withdrawn: | J6: -38954918
A7: Receipt No. | B7: Completion Time | C7: Initiation Time | D7: Details | E7: Transaction Status | F7: Paid In | G7: Withdrawn | H7: Balance | I7: Balance Confirmed | J7: Reason Type | K7: Other Party Info | L7: Linked Transaction ID | M7: A/C No. | N7: Currency
A8: UI2SB4Y11C | B8: 02-09-2026 23:35:58 | C8: 02-09-2026 23:35:58 | D8: Business Buy Goods Charge | E8: Completed | G8: -18 | H8: 8341383.6 | I8: true | J8: Business Buy Goods via API | K8: SP | N8: KES
A9: UI2SB4Y11C | B9: 02-09-2026 23:35:58 | C9: 02-09-2026 23:35:58 | D9: Business Buy Goods at 686775 - NEW TAFRIJA RESTAURANT via API REF Bill Payment 254723836614 to 727654 | E9: Completed | G9: -1450 | H9: 8341401.6 | I9: true | J9: Business Buy Goods via API | K9: 686775 - NEW TAFRIJA RESTAURANT | N9: KES
A10: UI2SB4XZP4 | B10: 02-09-2026 22:11:30 | C10: 02-09-2026 22:11:30 | D10: Business Pay Bill Charge | E10: Completed | G10: -13 | H10: 8342851.6 | I10: true | J10: Business Pay Bill via API | K10: SP | N10: KES
A11: UI2SB4XZP4 | B11: 02-09-2026 22:11:30 | C11: 02-09-2026 22:11:30 | D11: Business Pay Bill via API to 714888 - LOOP BIZ Acc. 323989 | E11: Completed | G11: -750 | H11: 8342864.6 | I11: true | J11: Business Pay Bill via API | K11: 714888 - LOOP BIZ | M11: 323989 | N11: KES
A12: UI2SB4XY6A | B12: 02-09-2026 22:11:16 | C12: 02-09-2026 22:11:16 | D12: Business Buy Goods Charge | E12: Completed | G12: -39 | H12: 8343614.6 | I12: true | J12: Business Buy Goods via API | K12: SP | N12: KES
A13: UI2SB4XY6A | B13: 02-09-2026 22:11:16 | C13: 02-09-2026 22:11:16 | D13: Business Buy Goods at 871036 - OILIBYA TOM MBOYA via API REF Bill Payment 15115 to 871046 | E13: Completed | G13: -5000 | H13: 8343653.6 | I13: true | J13: Business Buy Goods via API | K13: 871036 - OILIBYA TOM MBOYA | N13: KES
A14: UI2SB4XV62 | B14: 02-09-2026 22:10:16 | C14: 02-09-2026 22:10:16 | D14: Business Buy Goods Charge | E14: Completed | G14: -39 | H14: 8348653.6 | I14: true | J14: Business Buy Goods via API | K14: SP | N14: KES
A15: UI2SB4XV62 | B15: 02-09-2026 22:10:16 | C15: 02-09-2026 22:10:16 | D15: Business Buy Goods at 871036 - OILIBYA TOM MBOYA via API REF Bill Payment 15111 to 871046 | E15: Completed | G15: -5000 | H15: 8348692.6 | I15: true | J15: Business Buy Goods via API | K15: 871036 - OILIBYA TOM MBOYA | N15: KES
A16: UI2SB4XR95 | B16: 02-09-2026 22:09:53 | C16: 02-09-2026 22:09:53 | D16: Business Buy Goods Charge | E16: Completed | G16: -39 | H16: 8353692.6 | I16: true | J16: Business Buy Goods via API | K16: SP | N16: KES
A17: UI2SB4XR95 | B17: 02-09-2026 22:09:53 | C17: 02-09-2026 22:09:53 | D17: Business Buy Goods at 5967480 - KENNEDY WAITHAKA MBURU via API REF Bill Payment 1625943 to 3564672 | E17: Completed | G17: -4300 | H17: 8353731.6 | I17: true | J17: Business Buy Goods via API | K17: 5967480 - KENNEDY WAITHAKA MBURU | N17: KES
A18: UI2SB4XWNW | B18: 02-09-2026 22:07:39 | C18: 02-09-2026 22:07:39 | D18: Business Buy Goods Charge | E18: Completed | G18: -39 | H18: 8358031.6 | I18: true | J18: Business Buy Goods via API | K18: SP | N18: KES
A19: UI2SB4XWNW | B19: 02-09-2026 22:07:39 | C19: 02-09-2026 22:07:39 | D19: Business Buy Goods at 871036 - OILIBYA TOM MBOYA via API REF Bill Payment 15112 to 871046 | E19: Completed | G19: -5000 | H19: 8358070.6 | I19: true | J19: Business Buy Goods via API | K19: 871036 - OILIBYA TOM MBOYA | N19: KES
A20: UI2SB4XZOC | B20: 02-09-2026 22:06:32 | C20: 02-09-2026 22:06:32 | D20: Business Buy Goods Charge | E20: Completed | G20: -39 | H20: 8363070.6 | I20: true | J20: Business Buy Goods via API | K20: SP | N20: KES
A21: UI2SB4XZOC | B21: 02-09-2026 22:06:32 | C21: 02-09-2026 22:06:32 | D21: Business Buy Goods at 871036 - OILIBYA TOM MBOYA via API REF Bill Payment 15109 to 871046 | E21: Completed | G21: -5000 | H21: 8363109.6 | I21: true | J21: Business Buy Goods via API | K21: 871036 - OILIBYA TOM MBOYA | N21: KES
A22: UI2SB4XWNB | B22: 02-09-2026 22:05:20 | C22: 02-09-2026 22:05:20 | D22: Business Buy Goods Charge | E22: Completed | G22: -54 | H22: 8368109.6 | I22: true | J22: Business Buy Goods via API | K22: SP | N22: KES
A23: UI2SB4XWNB | B23: 02-09-2026 22:05:20 | C23: 02-09-2026 22:05:20 | D23: Business Buy Goods at 5285574 - National Oil Githunguri 1 via API REF Bill Payment 17941 to 4906008 | E23: Completed | G23: -7900 | H23: 8368163.6 | I23: true | J23: Business Buy Goods via API | K23: 5285574 - National Oil Githunguri 1 | N23: KES
A24: UI2SB4XWKN | B24: 02-09-2026 21:58:43 | C24: 02-09-2026 21:58:43 | D24: Business Pay Bill Charge | E24: Completed | G24: -8 | H24: 8376063.6 | I24: true | J24: Business Pay Bill via API | K24: SP | N24: KES
A25: UI2SB4XWKN | B25: 02-09-2026 21:58:43 | C25: 02-09-2026 21:58:43 | D25: Business Pay Bill via API to 880100 - NCBA BANK KENYA PLC. Acc. 999810 | E25: Completed | G25: -150 | H25: 8376071.6 | I25: true | J25: Business Pay Bill via API | K25: 880100 - NCBA BANK KENYA PLC. | M25: 999810 | N25: KES
A26: UI2SB4XUYP | B26: 02-09-2026 21:48:00 | C26: 02-09-2026 21:48:00 | D26: Business Buy Goods Charge | E26: Completed | G26: -48 | H26: 8376221.6 | I26: true | J26: Business Buy Goods via API | K26: SP | N26: KES
A27: UI2SB4XUYP | B27: 02-09-2026 21:48:00 | C27: 02-09-2026 21:48:00 | D27: Business Buy Goods at 7248058 - RUBIS KOMAROCK via API REF Bill Payment 77483 to 9246253 | E27: Completed | G27: -5550 | H27: 8376269.6 | I27: true | J27: Business Buy Goods via API | K27: 7248058 - RUBIS KOMAROCK | N27: KES
A28: UI2SB4XR2E | B28: 02-09-2026 21:45:41 | C28: 02-09-2026 21:45:41 | D28: Business Pay Bill Charge | E28: Completed | G28: -25 | H28: 8381819.6 | I28: true | J28: Business Pay Bill via API | K28: SP | N28: KES
A29: UI2SB4XR2E | B29: 02-09-2026 21:45:41 | C29: 02-09-2026 21:45:41 | D29: Business Pay Bill via API to 4062755 - VILCOM NETWORKS LTD Acc. 2168789 | E29: Completed | G29: -2000 | H29: 8381844.6 | I29: true | J29: Business Pay Bill via API | K29: 4062755 - VILCOM NETWORKS LTD | M29: 2168789 | N29: KES
A30: UI2SB4XR0O | B30: 02-09-2026 21:40:13 | C30: 02-09-2026 21:40:13 | D30: Business Buy Goods Charge | E30: Completed | G30: -48 | H30: 8383844.6 | I30: true | J30: Business Buy Goods via API | K30: SP | N30: KES
A31: UI2SB4XR0O | B31: 02-09-2026 21:40:13 | C31: 02-09-2026 21:40:13 | D31: Business Buy Goods at 7248058 - RUBIS KOMAROCK via API REF Bill Payment 80420 to 9246253 | E31: Completed | G31: -6700 | H31: 8383892.6 | I31: true | J31: Business Buy Goods via API | K31: 7248058 - RUBIS KOMAROCK | N31: KES
A32: UI2SB4XQ20 | B32: 02-09-2026 21:28:00 | C32: 02-09-2026 21:27:59 | D32: Business Pay Bill via API to 400222 - Co-operative Bank Collection Account Acc. 1118738# | E32: Completed | G32: -8650 | H32: 8390592.6 | I32: true | J32: Business Pay Bill via API | K32: 400222 - Co-operative Bank Collection Account | M32: 1118738# | N32: KES
A33: UI2SB4XQ20 | B33: 02-09-2026 21:28:00 | C33: 02-09-2026 21:27:59 | D33: Business Pay Bill Charge | E33: Completed | G33: -54 | H33: 8399242.6 | I33: true | J33: Business Pay Bill via API | K33: SP | N33: KES
A34: UI2SB4XOIF | B34: 02-09-2026 21:21:15 | C34: 02-09-2026 21:21:15 | D34: Business Buy Goods Charge | E34: Completed | G34: -39 | H34: 8399296.6 | I34: true | J34: Business Buy Goods via API | K34: SP | N34: KES
A35: UI2SB4XOIF | B35: 02-09-2026 21:21:15 | C35: 02-09-2026 21:21:15 | D35: Business Buy Goods at 5504520 - GSE TRADERS LIMITED via API REF Bill Payment 77475 to 4998256 | E35: Completed | G35: -3700 | H35: 8399335.6 | I35: true | J35: Business Buy Goods via API | K35: 5504520 - GSE TRADERS LIMITED | N35: KES
A36: UI2SB4XLF1 | B36: 02-09-2026 21:13:48 | C36: 02-09-2026 21:13:48 | D36: Business Buy Goods Charge | E36: Completed | G36: -48 | H36: 8403035.6 | I36: true | J36: Business Buy Goods via API | K36: SP | N36: KES
A37: UI2SB4XLF1 | B37: 02-09-2026 21:13:48 | C37: 02-09-2026 21:13:48 | D37: Business Buy Goods at 836548 - Be Energy Kayole Petrol station via API REF Bill Payment 77487 to 821697 | E37: Completed | G37: -5750 | H37: 8403083.6 | I37: true | J37: Business Buy Goods via API | K37: 836548 - Be Energy Kayole Petrol station | N37: KES
A38: UI2SB4XS7Z | B38: 02-09-2026 21:13:37 | C38: 02-09-2026 21:13:37 | D38: Business Buy Goods Charge | E38: Completed | G38: -63 | H38: 8408833.6 | I38: true | J38: Business Buy Goods via API | K38: SP | N38: KES
A39: UI2SB4XS7Z | B39: 02-09-2026 21:13:37 | C39: 02-09-2026 21:13:37 | D39: Business Buy Goods at 968511 - Shell Machakos Service Station via API REF Bill Payment 15115 to 968512 | E39: Completed | G39: -12415 | H39: 8408896.6 | I39: true | J39: Business Buy Goods via API | K39: 968511 - Shell Machakos Service Station | N39: KES
A40: UI2SB4XOGR | B40: 02-09-2026 21:12:37 | C40: 02-09-2026 21:12:37 | D40: Business Buy Goods Charge | E40: Completed | G40: -63 | H40: 8421311.6 | I40: true | J40: Business Buy Goods via API | K40: SP | N40: KES
...

Sheet Sasapay stm
A1: Business Short Code | B1: Account Number | C1: Account Name | D1: Product Type | E1: Industry | F1: Transaction Type | G1: Debit | H1: Credit | I1: Charge Amount | J1: Service Fee | K1: SMS Charge Amount | L1: Collection Charge Amount | M1: Running Balance | N1: Transaction Date | O1: Transaction Code | P1: Third Party Transaction Code | Q1: Reversal Transaction Code | R1: Original Transaction Code | S1: Client Name | T1: From Channel | U1: To Channel | V1: Party B | W1: Party B Name | X1: Provider | Y1: Transaction Reference | Z1: Merchant Reference | AA1: Initiation Time | AB1: Reversal Status | AC1: Transaction Status | AD1: Platform | AE1: Result Code | AF1: Result Description
B2: 784176 | C2: Hizo Technology Limited | D2: Till | E2: Organisation | F2: Transaction Out | G2: 1780 | H2: 0 | I2: 10 | J2: 0 | K2: 1 | L2: 0 | M2: 120551.14 | N2: 46267 | O2: SWEJ7U8MQ4Z1O1F | P2: UI2SB4VYS8 | T2: SasaPay | U2: ThirdPartyBillPayment | V2: 4999930 | X2: Safaricom | Y2: W13841171 | Z2: 3fb92da8-1d57-43ce-b7ed-b97dfe3a649c | AA2: 46267.043 | AB2: Not Reversed | AC2: api | AD2: SUCCESS | AE2: SP00000 | AF2: Transaction completed successfully
B3: 80421 | C3: KBQ 732J | D3: Matatu | E3: Organisation | F3: Transaction Out | G3: 5650 | H3: 0 | I3: 15 | J3: 0 | K3: 1 | L3: 0 | M3: 36.934 | N3: 46267 | O3: SWEJ7U8M9TVRVWD | P3: UI2SB4W3H4 | T3: SasaPay | U3: ThirdPartyBillPayment | V3: 9246253 | X3: Safaricom | Y3: W13841941 | Z3: Fuel | AA3: 46267.215 | AB3: Not Reversed | AD3: SUCCESS | AE3: SP00000 | AF3: Transaction completed successfully
B4: 77489 | C4: KBU 351C | D4: Matatu | E4: Organisation | F4: Transaction Out | G4: 13650 | H4: 0 | I4: 15 | J4: 0 | K4: 1 | L4: 0 | M4: 11.15 | N4: 46267 | O4: SWEJ7U8NFFSX7WE | P4: UI2SB4WG3Q | T4: SasaPay | U4: ThirdPartyBillPayment | V4: 821697 | X4: Safaricom | Y4: W13842249 | Z4: Fuel | AA4: 46267.272 | AB4: Not Reversed | AD4: SUCCESS | AE4: SP00000 | AF4: Transaction completed successfully
B5: 77480 | C5: KBR 244Y | D5: Matatu | E5: Organisation | F5: Transaction Out | G5: 6700 | H5: 0 | I5: 15 | J5: 0 | K5: 1 | L5: 0 | M5: 21.98 | N5: 46267 | O5: SWEJ7U8NFHFDX44 | P5: UI2SB4WBNX | T5: SasaPay | U5: ThirdPartyBillPayment | V5: 821697 | X5: Safaricom | Y5: W13842255 | Z5: Fuel | AA5: 46267.272 | AB5: Not Reversed | AD5: SUCCESS | AE5: SP00000 | AF5: Transaction completed successfully
B6: 77487 | C6: KBY 456V | D6: Matatu | E6: Organisation | F6: Transaction Out | G6: 5400 | H6: 0 | I6: 15 | J6: 0 | K6: 1 | L6: 0 | M6: 33.796 | N6: 46267 | O6: SWEJ7U8NFI1398Z | P6: UI2SB4WHIQ | T6: SasaPay | U6: ThirdPartyBillPayment | V6: 821697 | X6: Safaricom | Y6: W13842259 | Z6: Fuel | AA6: 46267.273 | AB6: Not Reversed | AD6: SUCCESS | AE6: SP00000 | AF6: Transaction completed successfully
B7: 1586202 | C7: purity - Twiddle Pips | D7: Limited Personal Wallet | F7: Transaction Out | G7: 97486 | H7: 0 | I7: 15 | J7: 15 | K7: 0 | L7: 0 | M7: 3455 | N7: 46267 | O7: SWEJ7U8NKTMRLE3 | P7: UI2SB4WHX9 | T7: SasaPay | U7: ThirdPartyBillPayment | V7: 1586202 | X7: Safaricom | Y7: W13842697 | Z7: RZV9HXBQ | AA7: 46267.325 | AB7: Not Reversed | AD7: SUCCESS | AE7: SP00000 | AF7: Transaction completed successfully
A8: 756756 | B8: 254720233020 | C8: ALFRED GATONGA | D8: Limited Personal Wallet | F8: Transaction Out | G8: 1500 | H8: 0 | I8: 10 | J8: 0 | K8: 0 | L8: 0 | M8: 7232 | N8: 46267 | O8: SWEJ7U8NN8376XL | P8: UI2SB4WF8C | T8: SasaPay | U8: ThirdPartyBillPayment | V8: 634264 | X8: Safaricom | Y8: W13842961 | Z8: W13842961 | AA8: 46267.349 | AB8: Not Reversed | AC8: user_app | AD8: SUCCESS | AE8: SP00000 | AF8: Transaction completed successfully
A9: 756756 | B9: 254797413147 | C9: FELIX ODUOR | D9: Limited Personal Wallet | F9: Transaction Out | G9: 140 | H9: 0 | I9: 10 | J9: 0 | K9: 0 | L9: 0 | M9: 351 | N9: 46267 | O9: SWEJ7U8NOXUAGUH | P9: UI2SB4WJ6V | T9: SasaPay | U9: ThirdPartyBillPayment | V9: 6721699 | X9: Safaricom | Y9: W13843086 | Z9: W13843086 | AA9: 46267.36 | AB9: Not Reversed | AC9: user_app | AD9: SUCCESS | AE9: SP00000 | AF9: Transaction completed successfully
A10: 455555 | B10: 343884 | C10: Michael Mboya | D10: Limited Personal Wallet | F10: Transaction Out | G10: 3465 | H10: 0 | I10: 10 | J10: 0 | K10: 0 | L10: 0 | M10: 5794 | N10: 46267 | O10: SWEJ7U8NO3GU1SL | P10: UI2SN2T1MB | T10: SasaPay | U10: ThirdPartyBillPayment | V10: 9053691 | X10: Safaricom | Y10: W13843135 | Z10: W13843135 | AA10: 46267.362 | AB10: Not Reversed | AC10: user_app | AD10: SUCCESS | AE10: SP00000 | AF10: Transaction completed successfully
B11: 293009 | C11: Adeline Munguti | D11: Till | F11: Transaction Out | G11: 7363 | H11: 0 | I11: 57 | J11: 0 | K11: 0 | L11: 0 | M11: 389832 | N11: 46267 | O11: SWEJ7U8NPR9X7CR | P11: UI2SB4WKRW | S11: DAVIS AND SHIRTLIFF LIMITED | T11: SasaPay | U11: ThirdPartyBillPayment | V11: 293009 | W11: DAVIS AND SHIRTLIFF LIMITED | X11: Safaricom | Y11: W13843325 | Z11: a499805a-4877-47ee-8311-9d2500b53dbd | AA11: 46267.372 | AB11: Not Reversed | AD11: SUCCESS | AE11: SP00000 | AF11: Transaction completed successfully
B12: 15114 | C12: Umowa Sacco - KDY 537B | D12: Matatu | E12: Organisation | F12: Transaction Out | G12: 6000 | H12: 0 | I12: 15 | J12: 0 | K12: 1 | L12: 0 | M12: 13608.612 | N12: 46267 | O12: SWEJ7U8NPVAOAI8 | P12: UI2SB4WFJ7 | T12: SasaPay | U12: ThirdPartyBillPayment | V12: 968512 | X12: Safaricom | Y12: W13843347 | Z12: fuel | AA12: 46267.374 | AB12: Not Reversed | AD12: SUCCESS | AE12: SP00000 | AF12: Transaction completed successfully
B13: 414936 | C13: John Slater | D13: Limited Personal Wallet | F13: Transaction Out | G13: 1500 | H13: 0 | I13: 25 | J13: 2 | K13: 0 | L13: 0 | M13: 21326 | N13: 46267 | O13: SWEJ7U8NSU29DL3 | P13: UI2SB4WKYX | S13: KCB Paybill AC | T13: SasaPay | U13: ThirdPartyBillPayment | V13: 414936 | W13: KCB Paybill AC | X13: Safaricom | Y13: W13843684 | Z13: ACWTGA9V | AA13: 46267.391 | AB13: Not Reversed | AD13: SUCCESS | AE13: SP00000 | AF13: Transaction completed successfully
B14: 15111 | C14: Umowa Sacco - KDY 586B | D14: Matatu | E14: Organisation | F14: Transaction Out | G14: 10000 | H14: 0 | I14: 15 | J14: 0 | K14: 1 | L14: 0 | M14: 1124.458 | N14: 46267 | O14: SWEJ7U8NTA6RA6Y | P14: UI2SB4WHAH | T14: SasaPay | U14: ThirdPartyBillPayment | V14: 9926197 | X14: Safaricom | Y14: W13843802 | Z14: vincent recovery | AA14: 46267.398 | AB14: Not Reversed | AD14: SUCCESS | AE14: SP00000 | AF14: Transaction completed successfully
A15: 756756 | B15: 1625943 | C15: Kennedy - Kennedy waithaka mburu | D15: Biashara Wallet | F15: Transaction Out | G15: 2700 | H15: 0 | I15: 40 | J15: 0 | K15: 0 | L15: 0 | M15: 1305.23 | N15: 46267 | O15: SWEJ7U8NTKW9JJ2 | P15: UI2SB4WIRN | S15: Rubis Energy Kenya PLc | T15: SasaPay | U15: ThirdPartyBillPayment | V15: 485111 | W15: Rubis Energy Kenya PLc | X15: Safaricom | Y15: W13843860 | Z15: 6500090405 | AA15: 46267.402 | AB15: Not Reversed | AC15: user_app | AD15: SUCCESS | AE15: SP00000 | AF15: Transaction completed successfully
B16: 1484 | C16: VLC- OFFICE PETTY CASH | D16: Till | E16: Organisation | F16: Transaction Out | G16: 900 | H16: 0 | I16: 20 | J16: 0 | K16: 1 | L16: 0 | M16: 1328.674 | N16: 46267 | O16: SWEJ7U8NTTD3W0C | P16: UI2SB4WP5U | S16: Equity Paybill Account | T16: SasaPay | U16: ThirdPartyBillPayment | V16: 247247 | W16: Equity Paybill Account | X16: Safaricom | Y16: W13843926 | Z16: 116700 | AA16: 46267.406 | AB16: Not Reversed | AD16: SUCCESS | AE16: SP00000 | AF16: Transaction completed successfully
A17: 756756 | B17: 254795093834 | C17: Victor Omondi | D17: Limited Personal Wallet | F17: Transaction Out | G17: 20 | H17: 0 | I17: 0 | J17: 0 | K17: 0 | L17: 0 | M17: 56 | N17: 46267 | O17: SWEJ7U8NWDUY7OU | P17: UI2SB4WQSQ | S17: Pharmaplus Pharmaceuticals_23 | T17: SasaPay | U17: ThirdPartyBillPayment | V17: 4131085 | W17: Pharmaplus Pharmaceuticals_23 | X17: Safaricom | Y17: W13844095 | Z17: n | AA17: 46267.417 | AB17: Not Reversed | AC17: user_app | AD17: SUCCESS | AE17: SP00000 | AF17: Transaction completed successfully
B18: 458445 | C18: BUYSIMU TECHNOLOGIES LIMITED | D18: Till | E18: Organisation | F18: Transaction Out | G18: 22500 | H18: 0 | I18: 87 | J18: 0 | K18: 1 | L18: 0 | M18: 810922.69 | N18: 46267 | O18: SWEJ7U8NW2RW18S | P18: UI2SB4WMJ0 | S18: LOOP BIZ | T18: SasaPay | U18: ThirdPartyBillPayment | V18: 714888 | W18: LOOP BIZ | X18: Safaricom | Y18: W13844344 | Z18: 18738 | AA18: 46267.427 | AB18: Not Reversed | AC18: api | AD18: SUCCESS | AE18: SP00000 | AF18: Transaction completed successfully
A19: 756756 | B19: 254711592002 | C19: Leonard Gitachu | D19: Limited Personal Wallet | F19: Transaction Out | G19: 1500 | H19: 0 | I19: 10 | J19: 0 | K19: 0 | L19: 0 | M19: 11723 | N19: 46267 | O19: SWEJ7U8NW7XCO14 | P19: UI2SB4WK05 | T19: SasaPay | U19: ThirdPartyBillPayment | V19: 5555550 | X19: Safaricom | Y19: W13844375 | Z19: W13844375 | AA19: 46267.429 | AB19: Not Reversed | AC19: user_app | AD19: SUCCESS | AE19: SP00000 | AF19: Transaction completed successfully
B20: 225544 | C20: Absolute Shop | D20: AgencyShop | E20: Wholesale and Retail trade | F20: Transaction Out | G20: 10 | H20: 0 | I20: 0 | J20: 0 | K20: 0 | L20: 0 | M20: 148.16 | N20: 46267 | O20: SWEJ7U8NX2VAZD4 | Q20: RVHGT0KB61V | T20: SasaPay | U20: ThirdPartyBillPayment | V20: 479068 | X20: Safaricom | Y20: W13844597 | Z20: 301210 | AA20: 46267.442 | AB20: Reversed | AD20: FAILED | AE20: SP01002 | AF20: 1:The balance is insufficient for the transaction.
B21: 1552342 | C21: Monica jematia chemuna | D21: Limited Personal Wallet | F21: Transaction Out | G21: 15900 | H21: 0 | I21: 82 | J21: 18 | K21: 0 | L21: 0 | M21: 50 | N21: 46267 | O21: SWEJ7U8NYA5FJ4W | P21: UI2SB4WK79 | S21: Equity Paybill Account | T21: SasaPay | U21: ThirdPartyBillPayment | V21: 1552342 | W21: Equity Paybill Account | X21: Safaricom | Y21: W13844676 | Z21: N5H4LRSL | AA21: 46267.446 | AB21: Not Reversed | AD21: SUCCESS | AE21: SP00000 | AF21: Transaction completed successfully
A22: 455555 | B22: 334660 | C22: GRACE MBERA | D22: Limited Personal Wallet | F22: Transaction Out | G22: 2400 | H22: 0 | I22: 34 | J22: 0 | K22: 0 | L22: 0 | M22: 3509 | N22: 46267 | O22: SWEJ7U8NYY8KFWM | P22: UI2SN2T4NH | S22: CIC Money Market Fund | T22: SasaPay | U22: ThirdPartyBillPayment | V22: 600118 | W22: CIC Money Market Fund | X22: Safaricom | Y22: W13844792 | Z22: 182779 | AA22: 46267.456 | AB22: Not Reversed | AC22: user_app | AD22: SUCCESS | AE22: SP00000 | AF22: Transaction completed successfully
B23: 1326697 | C23: Kenneth Njoroge Nganga | D23: Limited Personal Wallet | F23: Transaction Out | G23: 60 | H23: 0 | I23: 0 | J23: 0 | K23: 0 | L23: 0 | M23: 13461 | N23: 46267 | O23: SWEJ7U8NY0SR33K | P23: UI2SB4WMW0 | T23: SasaPay | U23: ThirdPartyBillPayment | V23: 1326697 | X23: Safaricom | Y23: W13844799 | Z23: I0VE48YU | AA23: 46267.456 | AB23: Not Reversed | AD23: SUCCESS | AE23: SP00000 | AF23: Transaction completed successfully
B24: 276585 | C24: HEAVENLY WINGS FOODS LIMITED | D24: Till | E24: Organisation | F24: Transaction Out | G24: 9450 | H24: 0 | I24: 15 | J24: 0 | K24: 1 | L24: 0 | M24: 23525.36 | N24: 46267 | O24: SWEJ7U8NY2FVS9C | P24: UI2SB4WPQ8 | T24: SasaPay | U24: ThirdPartyBillPayment | V24: 3586381 | X24: Safaricom | Y24: W13844809 | Z24: Dry Goods purchase | AA24: 46267.457 | AB24: Not Reversed | AD24: SUCCESS | AE24: SP00000 | AF24: Transaction completed successfully
B25: 276585 | C25: HEAVENLY WINGS FOODS LIMITED | D25: Till | E25: Organisation | F25: Transaction Out | G25: 8120 | H25: 0 | I25: 15 | J25: 0 | K25: 1 | L25: 0 | M25: 13769.36 | N25: 46267 | O25: SWEJ7U8N0ZQK5EZ | P25: UI2SB4WSPF | T25: SasaPay | U25: ThirdPartyBillPayment | V25: 5775191 | X25: Safaricom | Y25: W13844860 | Z25: Purchase of sausages, bacon | AA25: 46267.458 | AB25: Not Reversed | AD25: SUCCESS | AE25: SP00000 | AF25: Transaction completed successfully
B26: 458445 | C26: BUYSIMU TECHNOLOGIES LIMITED | D26: Till | E26: Organisation | F26: Transaction Out | G26: 20000 | H26: 0 | I26: 82 | J26: 0 | K26: 1 | L26: 0 | M26: 761775.69 | N26: 46267 | O26: SWEJ7U8N0ZU2KWQ | P26: UI2SB4WPR0 | S26: Africastalking Ltd | T26: SasaPay | U26: ThirdPartyBillPayment | V26: 525900 | W26: Africastalking Ltd | X26: Safaricom | Y26: W13844863 | Z26: ASFASMS | AA26: 46267.458 | AB26: Not Reversed | AD26: SUCCESS | AE26: SP00000 | AF26: Transaction completed successfully
B27: 276585 | C27: HEAVENLY WINGS FOODS LIMITED | D27: Till | E27: Organisation | F27: Transaction Out | G27: 650 | H27: 0 | I27: 10 | J27: 0 | K27: 1 | L27: 0 | M27: 13108.36 | N27: 46267 | O27: SWEJ7U8N02X9DQO | P27: UI2SB4WMXS | T27: SasaPay | U27: ThirdPartyBillPayment | V27: 331711 | X27: Safaricom | Y27: W13844880 | Z27: Purchase of packaging bags | AA27: 46267.46 | AB27: Not Reversed | AD27: SUCCESS | AE27: SP00000 | AF27: Transaction completed successfully
A28: 756756 | B28: 358222 | C28: Dunwell - TUMAINI SHOP | D28: Matatu | F28: Transaction Out | G28: 3720 | H28: 0 | I28: 49 | J28: 0 | K28: 0 | L28: 0 | M28: 850.22 | N28: 46267 | O28: SWEJ7U8N1UWPKWF | P28: UI2SB4WRFJ | S28: HAWKERS PRIDE ENTERPRISES LIMITED | T28: SasaPay | U28: ThirdPartyBillPayment | V28: 4107991 | W28: HAWKERS PRIDE ENTERPRISES LIMITED | X28: Safaricom | Y28: W13845063 | Z28: 3 | AA28: 46267.472 | AB28: Not Reversed | AC28: user_app | AD28: SUCCESS | AE28: SP00000 | AF28: Transaction completed successfully
B29: 1003020 | C29: Stephen - Viewtech Afya | D29: Till-CustomerOption | F29: Transaction Out | G29: 3860 | H29: 0 | I29: 49 | J29: 38.6 | K29: 0 | L29: 0 | M29: 41918.93 | N29: 46267 | O29: SWEJ7U8N2JVF3NG | P29: UI2SB4WSYZ | S29: GURU NANAK RAMGARHIA SIKH HOSPITAL | T29: SasaPay | U29: ThirdPartyBillPayment | V29: 1003020 | W29: GURU NANAK RAMGARHIA SIKH HOSPITAL | X29: Safaricom | Y29: W13845310 | Z29: MF166661 | AA29: 46267.482 | AB29: Not Reversed | AD29: SUCCESS | AE29: SP00000 | AF29: Transaction completed successfully
A30: 756756 | B30: 254708619405 | C30: Dennis Mwangi | D30: Wallet-Personal | F30: Transaction Out | G30: 150 | H30: 0 | I30: 10 | J30: 0 | K30: 0 | L30: 0 | M30: 1272 | N30: 46267 | O30: SWEJ7U8N2NDOM1Y | P30: UI2SB4WN6Z | T30: SasaPay | U30: ThirdPartyBillPayment | V30: 9981521 | X30: Safaricom | Y30: W13845341 | Z30: W13845341 | AA30: 46267.483 | AB30: Not Reversed | AC30: user_app | AD30: SUCCESS | AE30: SP00000 | AF30: Transaction completed successfully
A31: 756756 | B31: 205756 | C31: Erick - erick | D31: Biashara Wallet | F31: Transaction Out | G31: 100 | H31: 0 | I31: 0 | J31: 0 | K31: 0 | L31: 0 | M31: 364.59 | N31: 46267 | O31: SWEJ7U8N2YBIDU7 | P31: UI2SB4WN9Q | T31: SasaPay | U31: ThirdPartyBillPayment | V31: 5047675 | X31: Safaricom | Y31: W13845433 | Z31: W13845433 | AA31: 46267.488 | AB31: Not Reversed | AC31: user_app | AD31: SUCCESS | AE31: SP00000 | AF31: Transaction completed successfully
B32: 520420 | C32: Cynthia Tiany | D32: Limited Personal Wallet | F32: Transaction Out | G32: 49350 | H32: 0 | I32: 15 | J32: 15 | K32: 0 | L32: 0 | M32: 90985.224 | N32: 46267 | O32: SWEJ7U8N2YWPBE6 | P32: UI2SB4WTY4 | T32: SasaPay | U32: ThirdPartyBillPayment | V32: 520420 | X32: Safaricom | Y32: W13845440 | Z32: JL1H1FGF | AA32: 46267.488 | AB32: Not Reversed | AD32: SUCCESS | AE32: SP00000 | AF32: Transaction completed successfully
B33: 118594 | C33: Petty Cash | D33: Till | E33: Financial and Insurance activities | F33: Transaction Out | G33: 960 | H33: 0 | I33: 20 | J33: 0 | K33: 1 | L33: 0 | M33: 42846.58 | N33: 46267 | O33: SWEJ7U8N2ZYXT3W | P33: UI2SB4WT29 | S33: Lipa na KCB | T33: SasaPay | U33: ThirdPartyBillPayment | V33: 522533 | W33: Lipa na KCB | X33: Safaricom | Y33: W13845447 | Z33: 7881524 | AA33: 46267.489 | AB33: Not Reversed | AD33: SUCCESS | AE33: SP00000 | AF33: Transaction completed successfully
B34: 1606341 | C34: Beldina - Beldina | D34: Limited Personal Wallet | F34: Transaction Out | G34: 675 | H34: 0 | I34: 10 | J34: 2 | K34: 0 | L34: 0 | M34: 312 | N34: 46267 | O34: SWEJ7U8N27CT8EP | P34: UI2SB4WQ67 | T34: SasaPay | U34: ThirdPartyBillPayment | V34: 1606341 | X34: Safaricom | Y34: W13845498 | Z34: NRNYDA0Q | AA34: 46267.492 | AB34: Not Reversed | AD34: SUCCESS | AE34: SP00000 | AF34: Transaction completed successfully
A35: 756756 | B35: 254742451519 | C35: Bethwel Ogot | D35: Limited Personal Wallet | F35: Transaction Out | G35: 18000 | H35: 0 | I35: 80 | J35: 0 | K35: 0 | L35: 0 | M35: 49363 | N35: 46267 | O35: SWEJ7U8N5V19CC9 | P35: UI2SB4WU5B | S35: Co | T35: SasaPay | U35: ThirdPartyBillPayment | V35: 400200 | W35: Co | X35: Safaricom | Y35: W13845825 | Z35: 01116560460900 | AA35: 46267.505 | AB35: Not Reversed | AC35: user_app | AD35: SUCCESS | AE35: SP00000 | AF35: Transaction completed successfully
A36: 756756 | B36: 254742451519 | C36: Bethwel Ogot | D36: Limited Personal Wallet | F36: Transaction Out | G36: 25000 | H36: 0 | I36: 87 | J36: 0 | K36: 0 | L36: 0 | M36: 21756 | N36: 46267 | O36: SWEJ7U8N51OWDOF | P36: UI2SB4WU5V | S36: Stima SACCO Society ltd | T36: SasaPay | U36: ThirdPartyBillPayment | V36: 823244 | W36: Stima SACCO Society ltd | X36: Safaricom | Y36: W13845914 | Z36: 801047054501 | AA36: 46267.507 | AB36: Not Reversed | AC36: user_app | AD36: SUCCESS | AE36: SP00000 | AF36: Transaction completed successfully
A37: 756756 | B37: 1116456 | C37: SIMON - SIMON KATUMO MUTINDA | D37: Biashara Wallet | F37: Transaction Out | G37: 500 | H37: 0 | I37: 10 | J37: 0 | K37: 0 | L37: 0 | M37: 61160.02 | N37: 46267 | O37: SWEJ7U8N6EVPUST | P37: UI2SB4WQDX | T37: SasaPay | U37: ThirdPartyBillPayment | V37: 4106574 | X37: Safaricom | Y37: W13846034 | Z37: W13846034 | AA37: 46267.512 | AB37: Not Reversed | AC37: user_app | AD37: SUCCESS | AE37: SP00000 | AF37: Transaction completed successfully
B38: 110311 | C38: Bag Ware Limited | D38: PayBill-CustomerOption | E38: Organisation | F38: Transaction Out | G38: 20000 | H38: 0 | I38: 80 | J38: 0 | K38: 1 | L38: 0 | M38: 828713 | N38: 46267 | O38: SWEJ7U8N6LMWRA1 | P38: UI2SB4WNKB | S38: Guaranty Trust Bank Ltd | T38: SasaPay | U38: ThirdPartyBillPayment | V38: 910200 | W38: Guaranty Trust Bank Ltd | X38: Safaricom | Y38: W13846110 | Z38: 2210003653 | AA38: 46267.515 | AB38: Not Reversed | AD38: SUCCESS | AE38: SP00000 | AF38: Transaction completed successfully
B39: 453498 | C39: Alex ian Madara | D39: Limited Personal Wallet | F39: Transaction Out | G39: 300 | H39: 0 | I39: 10 | J39: 2 | K39: 0 | L39: 0 | M39: 10003 | N39: 46267 | O39: SWEJ7U8N6R2KDGU | P39: UI2SB4WVP2 | T39: SasaPay | U39: ThirdPartyBillPayment | V39: 453498 | X39: Safaricom | Y39: W13846166 | Z39: C7K5CXRC | AA39: 46267.518 | AB39: Not Reversed | AD39: SUCCESS | AE39: SP00000 | AF39: Transaction completed successfully
B40: 9235 | C40: Wimssy | D40: Till | E40: Organisation | F40: Transaction Out | G40: 8060 | H40: 0 | I40: 63 | J40: 0 | K40: 1 | L40: 0 | M40: 360317 | N40: 46267 | O40: SWEJ7U8N6TSA69H | P40: UI2SB4WVPJ | S40: GDC SACCO SOCIETY LTD | T40: SasaPay | U40: ThirdPartyBillPayment | V40: 639498 | W40: GDC SACCO SOCIETY LTD | X40: Safaricom | Y40: W13846185 | Z40: HtAZvGWUlerLT6OI40kr | AA40: 46267.519 | AB40: Not Reversed | AC40: api | AD40: SUCCESS | AE40: SP00000 | AF40: Transaction completed successfully
...

Sheet Working
A1: Receipt No. | B1: Completion Time | C1: Initiation Time | D1: Details | E1: Transaction Status | F1: Paid In | G1: Withdrawn | H1: Balance | I1: Balance Confirmed | J1: Reason Type | K1: Other Party Info | L1: Linked Transaction ID | M1: A/C No. | O1: Business Short Code | P1: Account Number | Q1: Account Name | R1: Product Type | S1: Industry | T1: Transaction Type | U1: Debit | W1: Credit | X1: Charge Amount | Y1: Service Fee | Z1: SMS Charge Amount | AA1: Collection Charge Amount | AB1: Running Balance | AC1: Transaction Date | AD1: Transaction Code | AE1: Third Party Transaction Code | AF1: Reversal Transaction Code | AG1: Original Transaction Code | AH1: Client Name | AI1: From Channel | AJ1: To Channel | AK1: Party B | AL1: Party B Name | AM1: Provider | AN1: Transaction Reference | AO1: Merchant Reference | AP1: Initiation Time | AQ1: Reversal Status | AR1: Transaction Status | AS1: Platform | AT1: Result Code | AU1: Result Description
A2: UI2SB4VYS8 | B2: 02-09-2026 01:02:30 | C2: 02-09-2026 01:02:30 | D2: Business Buy Goods at 3554057 - CHICKING - LAVINGTON via API REF Bill Payment 784176 to 4999930 | E2: Completed | G2: -1780 | H2: 28661758 | I2: true | J2: Business Buy Goods via API | K2: 3554057 - CHICKING - LAVINGTON | P2: 784176 | Q2: Hizo Technology Limited | R2: Till | S2: Organisation | T2: Transaction Out | U2: 1780 | V2: =G2+U2 -> 0 | W2: 0 | X2: 10 | Y2: 0 | Z2: 1 | AA2: 0 | AB2: 120551.14 | AC2: 46267 | AD2: SWEJ7U8MQ4Z1O1F | AE2: UI2SB4VYS8 | AI2: SasaPay | AJ2: ThirdPartyBillPayment | AK2: 4999930 | AM2: Safaricom | AN2: W13841171 | AO2: 3fb92da8-1d57-43ce-b7ed-b97dfe3a649c | AP2: 46267.043 | AQ2: Not Reversed | AR2: api | AS2: SUCCESS | AT2: SP00000 | AU2: Transaction completed successfully
A3: UI2SB4W3H4 | B3: 02-09-2026 05:09:17 | C3: 02-09-2026 05:09:16 | D3: Business Buy Goods at 7248058 - RUBIS KOMAROCK via API REF Bill Payment 80421 to 9246253 | E3: Completed | G3: -5650 | H3: 28656083 | I3: true | J3: Business Buy Goods via API | K3: 7248058 - RUBIS KOMAROCK | P3: 80421 | Q3: KBQ 732J | R3: Matatu | S3: Organisation | T3: Transaction Out | U3: 5650 | V3: =G3+U3 -> 0 | W3: 0 | X3: 15 | Y3: 0 | Z3: 1 | AA3: 0 | AB3: 36.934 | AC3: 46267 | AD3: SWEJ7U8M9TVRVWD | AE3: UI2SB4W3H4 | AI3: SasaPay | AJ3: ThirdPartyBillPayment | AK3: 9246253 | AM3: Safaricom | AN3: W13841941 | AO3: Fuel | AP3: 46267.215 | AQ3: Not Reversed | AS3: SUCCESS | AT3: SP00000 | AU3: Transaction completed successfully
A4: UI2SB4WBNX | B4: 02-09-2026 06:32:24 | C4: 02-09-2026 06:32:24 | D4: Business Buy Goods at 836548 - Be Energy Kayole Petrol station via API REF Bill Payment 77480 to 821697 | E4: Completed | G4: -6700 | H4: 28635622 | I4: true | J4: Business Buy Goods via API | K4: 836548 - Be Energy Kayole Petrol station | P4: 77480 | Q4: KBR 244Y | R4: Matatu | S4: Organisation | T4: Transaction Out | U4: 6700 | V4: =G4+U4 -> 0 | W4: 0 | X4: 15 | Y4: 0 | Z4: 1 | AA4: 0 | AB4: 21.98 | AC4: 46267 | AD4: SWEJ7U8NFHFDX44 | AE4: UI2SB4WBNX | AI4: SasaPay | AJ4: ThirdPartyBillPayment | AK4: 821697 | AM4: Safaricom | AN4: W13842255 | AO4: Fuel | AP4: 46267.272 | AQ4: Not Reversed | AS4: SUCCESS | AT4: SP00000 | AU4: Transaction completed successfully
A5: UI2SB4WF8C | B5: 02-09-2026 08:23:14 | C5: 02-09-2026 08:23:14 | D5: Business Buy Goods at 634263 - TotalEnergies Lexo Utawala Junction via API REF Bill Payment 254720233020 to 634264 | E5: Completed | G5: -1500 | H5: 28531025 | I5: true | J5: Business Buy Goods via API | K5: 634263 - TotalEnergies Lexo Utawala Junction | O5: 756756 | P5: 254720233020 | Q5: ALFRED GATONGA | R5: Limited Personal Wallet | T5: Transaction Out | U5: 1500 | V5: =G5+U5 -> 0 | W5: 0 | X5: 10 | Y5: 0 | Z5: 0 | AA5: 0 | AB5: 7232 | AC5: 46267 | AD5: SWEJ7U8NN8376XL | AE5: UI2SB4WF8C | AI5: SasaPay | AJ5: ThirdPartyBillPayment | AK5: 634264 | AM5: Safaricom | AN5: W13842961 | AO5: W13842961 | AP5: 46267.349 | AQ5: Not Reversed | AR5: user_app | AS5: SUCCESS | AT5: SP00000 | AU5: Transaction completed successfully
A6: UI2SB4WFJ7 | B6: 02-09-2026 08:58:31 | C6: 02-09-2026 08:58:30 | D6: Business Buy Goods at 968511 - Shell Machakos Service Station via API REF Bill Payment 15114 to 968512 | E6: Completed | G6: -6000 | H6: 28517448 | I6: true | J6: Business Buy Goods via API | K6: 968511 - Shell Machakos Service Station | P6: 15114 | Q6: Umowa Sacco - KDY 537B | R6: Matatu | S6: Organisation | T6: Transaction Out | U6: 6000 | V6: =G6+U6 -> 0 | W6: 0 | X6: 15 | Y6: 0 | Z6: 1 | AA6: 0 | AB6: 13608.612 | AC6: 46267 | AD6: SWEJ7U8NPVAOAI8 | AE6: UI2SB4WFJ7 | AI6: SasaPay | AJ6: ThirdPartyBillPayment | AK6: 968512 | AM6: Safaricom | AN6: W13843347 | AO6: fuel | AP6: 46267.374 | AQ6: Not Reversed | AS6: SUCCESS | AT6: SP00000 | AU6: Transaction completed successfully
A7: UI2SB4WG3Q | B7: 02-09-2026 06:31:26 | C7: 02-09-2026 06:31:26 | D7: Business Buy Goods at 836548 - Be Energy Kayole Petrol station via API REF Bill Payment 77489 to 821697 | E7: Completed | G7: -13650 | H7: 28642385 | I7: true | J7: Business Buy Goods via API | K7: 836548 - Be Energy Kayole Petrol station | P7: 77489 | Q7: KBU 351C | R7: Matatu | S7: Organisation | T7: Transaction Out | U7: 13650 | V7: =G7+U7 -> 0 | W7: 0 | X7: 15 | Y7: 0 | Z7: 1 | AA7: 0 | AB7: 11.15 | AC7: 46267 | AD7: SWEJ7U8NFFSX7WE | AE7: UI2SB4WG3Q | AI7: SasaPay | AJ7: ThirdPartyBillPayment | AK7: 821697 | AM7: Safaricom | AN7: W13842249 | AO7: Fuel | AP7: 46267.272 | AQ7: Not Reversed | AS7: SUCCESS | AT7: SP00000 | AU7: Transaction completed successfully
A8: UI2SB4WHAH | B8: 02-09-2026 09:33:22 | C8: 02-09-2026 09:33:22 | D8: Business Buy Goods at 6014631 - MERCY MUNYIVA KIOKO via API REF Bill Payment 15111 to 9926197 | E8: Completed | G8: -10000 | H8: 28505882 | I8: true | J8: Business Buy Goods via API | K8: 6014631 - MERCY MUNYIVA KIOKO | P8: 15111 | Q8: Umowa Sacco - KDY 586B | R8: Matatu | S8: Organisation | T8: Transaction Out | U8: 10000 | V8: =G8+U8 -> 0 | W8: 0 | X8: 15 | Y8: 0 | Z8: 1 | AA8: 0 | AB8: 1124.458 | AC8: 46267 | AD8: SWEJ7U8NTA6RA6Y | AE8: UI2SB4WHAH | AI8: SasaPay | AJ8: ThirdPartyBillPayment | AK8: 9926197 | AM8: Safaricom | AN8: W13843802 | AO8: vincent recovery | AP8: 46267.398 | AQ8: Not Reversed | AS8: SUCCESS | AT8: SP00000 | AU8: Transaction completed successfully
A9: UI2SB4WHIQ | B9: 02-09-2026 06:33:23 | C9: 02-09-2026 06:33:23 | D9: Business Buy Goods at 836548 - Be Energy Kayole Petrol station via API REF Bill Payment 77487 to 821697 | E9: Completed | G9: -5400 | H9: 28630174 | I9: true | J9: Business Buy Goods via API | K9: 836548 - Be Energy Kayole Petrol station | P9: 77487 | Q9: KBY 456V | R9: Matatu | S9: Organisation | T9: Transaction Out | U9: 5400 | V9: =G9+U9 -> 0 | W9: 0 | X9: 15 | Y9: 0 | Z9: 1 | AA9: 0 | AB9: 33.796 | AC9: 46267 | AD9: SWEJ7U8NFI1398Z | AE9: UI2SB4WHIQ | AI9: SasaPay | AJ9: ThirdPartyBillPayment | AK9: 821697 | AM9: Safaricom | AN9: W13842259 | AO9: Fuel | AP9: 46267.273 | AQ9: Not Reversed | AS9: SUCCESS | AT9: SP00000 | AU9: Transaction completed successfully
A10: UI2SB4WHX9 | B10: 02-09-2026 07:48:46 | C10: 02-09-2026 07:48:46 | D10: Business Buy Goods at 177545 - DONHOLM TOTAL S.S1 via API REF Bill Payment 1586202 to 177749 | E10: Completed | G10: -97486 | H10: 28532640 | I10: true | J10: Business Buy Goods via API | K10: 177545 - DONHOLM TOTAL S.S1 | P10: 1586202 | Q10: purity - Twiddle Pips | R10: Limited Personal Wallet | T10: Transaction Out | U10: 97486 | V10: =G10+U10 -> 0 | W10: 0 | X10: 15 | Y10: 15 | Z10: 0 | AA10: 0 | AB10: 3455 | AC10: 46267 | AD10: SWEJ7U8NKTMRLE3 | AE10: UI2SB4WHX9 | AI10: SasaPay | AJ10: ThirdPartyBillPayment | AK10: 1586202 | AM10: Safaricom | AN10: W13842697 | AO10: RZV9HXBQ | AP10: 46267.325 | AQ10: Not Reversed | AS10: SUCCESS | AT10: SP00000 | AU10: Transaction completed successfully
A11: UI2SB4WIRN | B11: 02-09-2026 09:39:12 | C11: 02-09-2026 09:39:10 | D11: Business Pay Bill via API to 485111 - Rubis Energy Kenya PLc Acc. 6500090405 | E11: Completed | G11: -2700 | H11: 28503098 | I11: true | J11: Business Pay Bill via API | K11: 485111 - Rubis Energy Kenya PLc | M11: 6500090405 | O11: 756756 | P11: 1625943 | Q11: Kennedy - Kennedy waithaka mburu | R11: Biashara Wallet | T11: Transaction Out | U11: 2700 | V11: =G11+U11 -> 0 | W11: 0 | X11: 40 | Y11: 0 | Z11: 0 | AA11: 0 | AB11: 1305.23 | AC11: 46267 | AD11: SWEJ7U8NTKW9JJ2 | AE11: UI2SB4WIRN | AH11: Rubis Energy Kenya PLc | AI11: SasaPay | AJ11: ThirdPartyBillPayment | AK11: 485111 | AL11: Rubis Energy Kenya PLc | AM11: Safaricom | AN11: W13843860 | AO11: 6500090405 | AP11: 46267.402 | AQ11: Not Reversed | AR11: user_app | AS11: SUCCESS | AT11: SP00000 | AU11: Transaction completed successfully
A12: UI2SB4WJ6V | B12: 02-09-2026 08:38:08 | C12: 02-09-2026 08:38:08 | D12: Business Buy Goods at 8561779 - FELIX ONYANGO ODUOR via API REF Bill Payment 254797413147 to 6721699 | E12: Completed | G12: -140 | H12: 28530867 | I12: true | J12: Business Buy Goods via API | K12: 8561779 - FELIX ONYANGO ODUOR | O12: 756756 | P12: 254797413147 | Q12: FELIX ODUOR | R12: Limited Personal Wallet | T12: Transaction Out | U12: 140 | V12: =G12+U12 -> 0 | W12: 0 | X12: 10 | Y12: 0 | Z12: 0 | AA12: 0 | AB12: 351 | AC12: 46267 | AD12: SWEJ7U8NOXUAGUH | AE12: UI2SB4WJ6V | AI12: SasaPay | AJ12: ThirdPartyBillPayment | AK12: 6721699 | AM12: Safaricom | AN12: W13843086 | AO12: W13843086 | AP12: 46267.36 | AQ12: Not Reversed | AR12: user_app | AS12: SUCCESS | AT12: SP00000 | AU12: Transaction completed successfully
A13: UI2SB4WK05 | B13: 02-09-2026 10:18:32 | C13: 02-09-2026 10:18:32 | D13: Business Buy Goods at 6569648 - SHELL MIREMA 1 via API REF Bill Payment 254711592002 to 5555550 | E13: Completed | G13: -1500 | H13: 28478091 | I13: true | J13: Business Buy Goods via API | K13: 6569648 - SHELL MIREMA 1 | O13: 756756 | P13: 254711592002 | Q13: Leonard Gitachu | R13: Limited Personal Wallet | T13: Transaction Out | U13: 1500 | V13: =G13+U13 -> 0 | W13: 0 | X13: 10 | Y13: 0 | Z13: 0 | AA13: 0 | AB13: 11723 | AC13: 46267 | AD13: SWEJ7U8NW7XCO14 | AE13: UI2SB4WK05 | AI13: SasaPay | AJ13: ThirdPartyBillPayment | AK13: 5555550 | AM13: Safaricom | AN13: W13844375 | AO13: W13844375 | AP13: 46267.429 | AQ13: Not Reversed | AR13: user_app | AS13: SUCCESS | AT13: SP00000 | AU13: Transaction completed successfully
A14: UI2SB4WK79 | B14: 02-09-2026 10:42:04 | C14: 02-09-2026 10:42:03 | D14: Business Pay Bill via API to 247247 - Equity Paybill Account Acc. 0766660011 | E14: Completed | G14: -15900 | H14: 28462105 | I14: true | J14: Business Pay Bill via API | K14: 247247 - Equity Paybill Account | M14: 0766660011 | P14: 1552342 | Q14: Monica jematia chemuna | R14: Limited Personal Wallet | T14: Transaction Out | U14: 15900 | V14: =G14+U14 -> 0 | W14: 0 | X14: 82 | Y14: 18 | Z14: 0 | AA14: 0 | AB14: 50 | AC14: 46267 | AD14: SWEJ7U8NYA5FJ4W | AE14: UI2SB4WK79 | AH14: Equity Paybill Account | AI14: SasaPay | AJ14: ThirdPartyBillPayment | AK14: 1552342 | AL14: Equity Paybill Account | AM14: Safaricom | AN14: W13844676 | AO14: N5H4LRSL | AP14: 46267.446 | AQ14: Not Reversed | AS14: SUCCESS | AT14: SP00000 | AU14: Transaction completed successfully
A15: UI2SB4WKRW | B15: 02-09-2026 08:56:48 | C15: 02-09-2026 08:56:48 | D15: Business Pay Bill via API to 600900 - DAVIS AND SHIRTLIFF LIMITED Acc. 355286 | E15: Completed | G15: -7363 | H15: 28523496 | I15: true | J15: Business Pay Bill via API | K15: 600900 - DAVIS AND SHIRTLIFF LIMITED | M15: 355286 | P15: 293009 | Q15: Adeline Munguti | R15: Till | T15: Transaction Out | U15: 7363 | V15: =G15+U15 -> 0 | W15: 0 | X15: 57 | Y15: 0 | Z15: 0 | AA15: 0 | AB15: 389832 | AC15: 46267 | AD15: SWEJ7U8NPR9X7CR | AE15: UI2SB4WKRW | AH15: DAVIS AND SHIRTLIFF LIMITED | AI15: SasaPay | AJ15: ThirdPartyBillPayment | AK15: 293009 | AL15: DAVIS AND SHIRTLIFF LIMITED | AM15: Safaricom | AN15: W13843325 | AO15: a499805a-4877-47ee-8311-9d2500b53dbd | AP15: 46267.372 | AQ15: Not Reversed | AS15: SUCCESS | AT15: SP00000 | AU15: Transaction completed successfully
A16: UI2SB4WKYX | B16: 02-09-2026 09:23:49 | C16: 02-09-2026 09:23:48 | D16: Business Pay Bill via API to 522522 - KCB Paybill AC Acc. 1107630282 | E16: Completed | G16: -1500 | H16: 28515900 | I16: true | J16: Business Pay Bill via API | K16: 522522 - KCB Paybill AC | M16: 1107630282 | P16: 414936 | Q16: John Slater | R16: Limited Personal Wallet | T16: Transaction Out | U16: 1500 | V16: =G16+U16 -> 0 | W16: 0 | X16: 25 | Y16: 2 | Z16: 0 | AA16: 0 | AB16: 21326 | AC16: 46267 | AD16: SWEJ7U8NSU29DL3 | AE16: UI2SB4WKYX | AH16: KCB Paybill AC | AI16: SasaPay | AJ16: ThirdPartyBillPayment | AK16: 414936 | AL16: KCB Paybill AC | AM16: Safaricom | AN16: W13843684 | AO16: ACWTGA9V | AP16: 46267.391 | AQ16: Not Reversed | AS16: SUCCESS | AT16: SP00000 | AU16: Transaction completed successfully
A17: UI2SB4WMJ0 | B17: 02-09-2026 10:15:20 | C17: 02-09-2026 10:15:20 | D17: Business Pay Bill via API to 714888 - LOOP BIZ Acc. 380605 | E17: Completed | G17: -22500 | H17: 28479665 | I17: true | J17: Business Pay Bill via API | K17: 714888 - LOOP BIZ | M17: 380605 | P17: 458445 | Q17: BUYSIMU TECHNOLOGIES LIMITED | R17: Till | S17: Organisation | T17: Transaction Out | U17: 22500 | V17: =G17+U17 -> 0 | W17: 0 | X17: 87 | Y17: 0 | Z17: 1 | AA17: 0 | AB17: 810922.69 | AC17: 46267 | AD17: SWEJ7U8NW2RW18S | AE17: UI2SB4WMJ0 | AH17: LOOP BIZ | AI17: SasaPay | AJ17: ThirdPartyBillPayment | AK17: 714888 | AL17: LOOP BIZ | AM17: Safaricom | AN17: W13844344 | AO17: 18738 | AP17: 46267.427 | AQ17: Not Reversed | AR17: api | AS17: SUCCESS | AT17: SP00000 | AU17: Transaction completed successfully
A18: UI2SB4WMW0 | B18: 02-09-2026 10:57:54 | C18: 02-09-2026 10:57:54 | D18: Business Buy Goods at 7267296 - JISTY FOOD via API REF Bill Payment 1326697 to 9242717 | E18: Completed | G18: -60 | H18: 28462045 | I18: true | J18: Business Buy Goods via API | K18: 7267296 - JISTY FOOD | P18: 1326697 | Q18: Kenneth Njoroge Nganga | R18: Limited Personal Wallet | T18: Transaction Out | U18: 60 | V18: =G18+U18 -> 0 | W18: 0 | X18: 0 | Y18: 0 | Z18: 0 | AA18: 0 | AB18: 13461 | AC18: 46267 | AD18: SWEJ7U8NY0SR33K | AE18: UI2SB4WMW0 | AI18: SasaPay | AJ18: ThirdPartyBillPayment | AK18: 1326697 | AM18: Safaricom | AN18: W13844799 | AO18: I0VE48YU | AP18: 46267.456 | AQ18: Not Reversed | AS18: SUCCESS | AT18: SP00000 | AU18: Transaction completed successfully
A19: UI2SB4WMXS | B19: 02-09-2026 11:02:38 | C19: 02-09-2026 11:02:38 | D19: Business Buy Goods at 331547 - TOWER GOLD PACKAGING VENTURES. via API REF Bill Payment 276585 to 331711 | E19: Completed | G19: -650 | H19: 28423646 | I19: true | J19: Business Buy Goods via API | K19: 331547 - TOWER GOLD PACKAGING VENTURES. | P19: 276585 | Q19: HEAVENLY WINGS FOODS LIMITED | R19: Till | S19: Organisation | T19: Transaction Out | U19: 650 | V19: =G19+U19 -> 0 | W19: 0 | X19: 10 | Y19: 0 | Z19: 1 | AA19: 0 | AB19: 13108.36 | AC19: 46267 | AD19: SWEJ7U8N02X9DQO | AE19: UI2SB4WMXS | AI19: SasaPay | AJ19: ThirdPartyBillPayment | AK19: 331711 | AM19: Safaricom | AN19: W13844880 | AO19: Purchase of packaging bags | AP19: 46267.46 | AQ19: Not Reversed | AS19: SUCCESS | AT19: SP00000 | AU19: Transaction completed successfully
A20: UI2SB4WN6Z | B20: 02-09-2026 11:36:50 | C20: 02-09-2026 11:36:50 | D20: Business Buy Goods at 6041758 - CENTRE MAX ONE TRADERS via API REF Bill Payment 254708619405 to 9981521 | E20: Completed | G20: -150 | H20: 28415825 | I20: true | J20: Business Buy Goods via API | K20: 6041758 - CENTRE MAX ONE TRADERS | O20: 756756 | P20: 254708619405 | Q20: Dennis Mwangi | R20: Wallet-Personal | T20: Transaction Out | U20: 150 | V20: =G20+U20 -> 0 | W20: 0 | X20: 10 | Y20: 0 | Z20: 0 | AA20: 0 | AB20: 1272 | AC20: 46267 | AD20: SWEJ7U8N2NDOM1Y | AE20: UI2SB4WN6Z | AI20: SasaPay | AJ20: ThirdPartyBillPayment | AK20: 9981521 | AM20: Safaricom | AN20: W13845341 | AO20: W13845341 | AP20: 46267.483 | AQ20: Not Reversed | AR20: user_app | AS20: SUCCESS | AT20: SP00000 | AU20: Transaction completed successfully
A21: UI2SB4WN9Q | B21: 02-09-2026 11:43:11 | C21: 02-09-2026 11:43:11 | D21: Business Buy Goods at 7045653 - KANGUNDO ROAD TOTAL PETROL STATION via API REF Bill Payment 205756 to 5047675 | E21: Completed | G21: -100 | H21: 28415717 | I21: true | J21: Business Buy Goods via API | K21: 7045653 - KANGUNDO ROAD TOTAL PETROL STATION | O21: 756756 | P21: 205756 | Q21: Erick - erick | R21: Biashara Wallet | T21: Transaction Out | U21: 100 | V21: =G21+U21 -> 0 | W21: 0 | X21: 0 | Y21: 0 | Z21: 0 | AA21: 0 | AB21: 364.59 | AC21: 46267 | AD21: SWEJ7U8N2YBIDU7 | AE21: UI2SB4WN9Q | AI21: SasaPay | AJ21: ThirdPartyBillPayment | AK21: 5047675 | AM21: Safaricom | AN21: W13845433 | AO21: W13845433 | AP21: 46267.488 | AQ21: Not Reversed | AR21: user_app | AS21: SUCCESS | AT21: SP00000 | AU21: Transaction completed successfully
A22: UI2SB4WNKB | B22: 02-09-2026 12:22:53 | C22: 02-09-2026 12:22:52 | D22: Business Pay Bill via API to 910200 - Guaranty Trust Bank Ltd Acc. 2210003653 | E22: Completed | G22: -20000 | H22: 28300870 | I22: true | J22: Business Pay Bill via API | K22: 910200 - Guaranty Trust Bank Ltd | M22: 2210003653 | P22: 110311 | Q22: Bag Ware Limited | R22: PayBill-CustomerOption | S22: Organisation | T22: Transaction Out | U22: 20000 | V22: =G22+U22 -> 0 | W22: 0 | X22: 80 | Y22: 0 | Z22: 1 | AA22: 0 | AB22: 828713 | AC22: 46267 | AD22: SWEJ7U8N6LMWRA1 | AE22: UI2SB4WNKB | AH22: Guaranty Trust Bank Ltd | AI22: SasaPay | AJ22: ThirdPartyBillPayment | AK22: 910200 | AL22: Guaranty Trust Bank Ltd | AM22: Safaricom | AN22: W13846110 | AO22: 2210003653 | AP22: 46267.515 | AQ22: Not Reversed | AS22: SUCCESS | AT22: SP00000 | AU22: Transaction completed successfully
A23: UI2SB4WOXB | B23: 02-09-2026 12:27:50 | C23: 02-09-2026 12:27:50 | D23: Business Pay Bill via API to 639498 - GDC SACCO SOCIETY LTD Acc. 4929856 | E23: Completed | G23: -3288 | H23: 28087883 | I23: true | J23: Business Pay Bill via API | K23: 639498 - GDC SACCO SOCIETY LTD | M23: 4929856 | P23: 9235 | Q23: Wimssy | R23: Till | S23: Organisation | T23: Transaction Out | U23: 3288 | V23: =G23+U23 -> 0 | W23: 0 | X23: 40 | Y23: 0 | Z23: 1 | AA23: 0 | AB23: 111280.4 | AC23: 46267 | AD23: SWEJ7U8N6TU5X4X | AE23: UI2SB4WOXB | AH23: GDC SACCO SOCIETY LTD | AI23: SasaPay | AJ23: ThirdPartyBillPayment | AK23: 639498 | AL23: GDC SACCO SOCIETY LTD | AM23: Safaricom | AN23: W13846198 | AO23: PRcP88t6cLRq4Qe69TF9 | AP23: 46267.519 | AQ23: Not Reversed | AR23: api | AS23: SUCCESS | AT23: SP00000 | AU23: Transaction completed successfully
A24: UI2SB4WOXC | B24: 02-09-2026 12:27:51 | C24: 02-09-2026 12:27:51 | D24: Business Pay Bill via API to 639498 - GDC SACCO SOCIETY LTD Acc. 876996574 | E24: Completed | G24: -372 | H24: 28048178 | I24: true | J24: Business Pay Bill via API | K24: 639498 - GDC SACCO SOCIETY LTD | M24: 876996574 | P24: 9235 | Q24: Wimssy | R24: Till | S24: Organisation | T24: Transaction Out | U24: 372 | V24: =G24+U24 -> 0 | W24: 0 | X24: 10 | Y24: 0 | Z24: 1 | AA24: 0 | AB24: 63629.6 | AC24: 46267 | AD24: SWEJ7U8N6TVNO6P | AE24: UI2SB4WOXC | AH24: GDC SACCO SOCIETY LTD | AI24: SasaPay | AJ24: ThirdPartyBillPayment | AK24: 639498 | AL24: GDC SACCO SOCIETY LTD | AM24: Safaricom | AN24: W13846211 | AO24: iJfvkuKnuCgnb4qQhTtl | AP24: 46267.519 | AQ24: Not Reversed | AR24: api | AS24: SUCCESS | AT24: SP00000 | AU24: Transaction completed successfully
A25: UI2SB4WOXE | B25: 02-09-2026 12:27:52 | C25: 02-09-2026 12:27:52 | D25: Business Pay Bill via API to 639498 - GDC SACCO SOCIETY LTD Acc. 28481045 | E25: Completed | G25: -2763 | H25: 28021948 | I25: true | J25: Business Pay Bill via API | K25: 639498 - GDC SACCO SOCIETY LTD | M25: 28481045 | P25: 9235 | Q25: Wimssy | R25: Till | S25: Organisation | T25: Transaction Out | U25: 2763 | V25: =G25+U25 -> 0 | W25: 0 | X25: 40 | Y25: 0 | Z25: 1 | AA25: 0 | AB25: 31245.6 | AC25: 46267 | AD25: SWEJ7U8N6TWVFDV | AE25: UI2SB4WOXE | AH25: GDC SACCO SOCIETY LTD | AI25: SasaPay | AJ25: ThirdPartyBillPayment | AK25: 639498 | AL25: GDC SACCO SOCIETY LTD | AM25: Safaricom | AN25: W13846212 | AO25: Ay8wdAWUfcAIvILjmR7r | AP25: 46267.519 | AQ25: Not Reversed | AR25: api | AS25: SUCCESS | AT25: SP00000 | AU25: Transaction completed successfully
A26: UI2SB4WOZA | B26: 02-09-2026 12:33:12 | C26: 02-09-2026 12:33:12 | D26: Business Buy Goods at 7213359 - VEROSHIMA TRADERS KAHAWA via API REF Bill Payment 1483 to 5228737 | E26: Completed | G26: -5920 | H26: 28000630 | I26: true | J26: Business Buy Goods via API | K26: 7213359 - VEROSHIMA TRADERS KAHAWA | P26: 1483 | Q26: VLC-PROPERTY PETTY CASH | R26: Till | S26: Organisation | T26: Transaction Out | U26: 5920 | V26: =G26+U26 -> 0 | W26: 0 | X26: 15 | Y26: 0 | Z26: 1 | AA26: 0 | AB26: 19695.578 | AC26: 46267 | AD26: SWEJ7U8N625YWZZ | AE26: UI2SB4WOZA | AI26: SasaPay | AJ26: ThirdPartyBillPayment | AK26: 5228737 | AM26: Safaricom | AN26: W13846323 | AO26: Purchase of construction materials - Richland Pointe | AP26: 46267.523 | AQ26: Not Reversed | AS26: SUCCESS | AT26: SP00000 | AU26: Transaction completed successfully
A27: UI2SB4WP5U | B27: 02-09-2026 09:44:23 | C27: 02-09-2026 09:44:23 | D27: Business Pay Bill via API to 247247 - Equity Paybill Account Acc. 116700 | E27: Completed | G27: -900 | H27: 28502198 | I27: true | J27: Business Pay Bill via API | K27: 247247 - Equity Paybill Account | M27: 116700 | P27: 1484 | Q27: VLC- OFFICE PETTY CASH | R27: Till | S27: Organisation | T27: Transaction Out | U27: 900 | V27: =G27+U27 -> 0 | W27: 0 | X27: 20 | Y27: 0 | Z27: 1 | AA27: 0 | AB27: 1328.674 | AC27: 46267 | AD27: SWEJ7U8NTTD3W0C | AE27: UI2SB4WP5U | AH27: Equity Paybill Account | AI27: SasaPay | AJ27: ThirdPartyBillPayment | AK27: 247247 | AL27: Equity Paybill Account | AM27: Safaricom | AN27: W13843926 | AO27: 116700 | AP27: 46267.406 | AQ27: Not Reversed | AS27: SUCCESS | AT27: SP00000 | AU27: Transaction completed successfully
A28: UI2SB4WPQ8 | B28: 02-09-2026 10:58:54 | C28: 02-09-2026 10:58:54 | D28: Business Buy Goods at 4321579 - SUNFALL GENERAL TRADERS LTD via API REF Bill Payment 276585 to 3586381 | E28: Completed | G28: -9450 | H28: 28452592 | I28: true | J28: Business Buy Goods via API | K28: 4321579 - SUNFALL GENERAL TRADERS LTD | P28: 276585 | Q28: HEAVENLY WINGS FOODS LIMITED | R28: Till | S28: Organisation | T28: Transaction Out | U28: 9450 | V28: =G28+U28 -> 0 | W28: 0 | X28: 15 | Y28: 0 | Z28: 1 | AA28: 0 | AB28: 23525.36 | AC28: 46267 | AD28: SWEJ7U8NY2FVS9C | AE28: UI2SB4WPQ8 | AI28: SasaPay | AJ28: ThirdPartyBillPayment | AK28: 3586381 | AM28: Safaricom | AN28: W13844809 | AO28: Dry Goods purchase | AP28: 46267.457 | AQ28: Not Reversed | AS28: SUCCESS | AT28: SP00000 | AU28: Transaction completed successfully
A29: UI2SB4WPR0 | B29: 02-09-2026 11:00:51 | C29: 02-09-2026 11:00:51 | D29: Business Pay Bill via API to 525900 - Africastalking Ltd Acc. ASFASMS | E29: Completed | G29: -20000 | H29: 28424364 | I29: true | J29: Business Pay Bill via API | K29: 525900 - Africastalking Ltd | M29: ASFASMS | P29: 458445 | Q29: BUYSIMU TECHNOLOGIES LIMITED | R29: Till | S29: Organisation | T29: Transaction Out | U29: 20000 | V29: =G29+U29 -> 0 | W29: 0 | X29: 82 | Y29: 0 | Z29: 1 | AA29: 0 | AB29: 761775.69 | AC29: 46267 | AD29: SWEJ7U8N0ZU2KWQ | AE29: UI2SB4WPR0 | AH29: Africastalking Ltd | AI29: SasaPay | AJ29: ThirdPartyBillPayment | AK29: 525900 | AL29: Africastalking Ltd | AM29: Safaricom | AN29: W13844863 | AO29: ASFASMS | AP29: 46267.458 | AQ29: Not Reversed | AS29: SUCCESS | AT29: SP00000 | AU29: Transaction completed successfully
A30: UI2SB4WQ67 | B30: 02-09-2026 11:48:58 | C30: 02-09-2026 11:48:58 | D30: Business Buy Goods at 6518431 - BLEJOMA SUPPLIES VIA NCBA via API REF Bill Payment 1606341 to 8811560 | E30: Completed | G30: -675 | H30: 28364601 | I30: true | J30: Business Buy Goods via API | K30: 6518431 - BLEJOMA SUPPLIES VIA NCBA | P30: 1606341 | Q30: Beldina - Beldina | R30: Limited Personal Wallet | T30: Transaction Out | U30: 675 | V30: =G30+U30 -> 0 | W30: 0 | X30: 10 | Y30: 2 | Z30: 0 | AA30: 0 | AB30: 312 | AC30: 46267 | AD30: SWEJ7U8N27CT8EP | AE30: UI2SB4WQ67 | AI30: SasaPay | AJ30: ThirdPartyBillPayment | AK30: 1606341 | AM30: Safaricom | AN30: W13845498 | AO30: NRNYDA0Q | AP30: 46267.492 | AQ30: Not Reversed | AS30: SUCCESS | AT30: SP00000 | AU30: Transaction completed successfully
A31: UI2SB4WQDX | B31: 02-09-2026 12:18:43 | C31: 02-09-2026 12:18:43 | D31: Business Buy Goods at 6707263 - SHELL TECO SERVICE STATION_Pump 5 via API REF Bill Payment 1116456 to 4106574 | E31: Completed | G31: -500 | H31: 28320946 | I31: true | J31: Business Buy Goods via API | K31: 6707263 - SHELL TECO SERVICE STATION_Pump 5 | O31: 756756 | P31: 1116456 | Q31: SIMON - SIMON KATUMO MUTINDA | R31: Biashara Wallet | T31: Transaction Out | U31: 500 | V31: =G31+U31 -> 0 | W31: 0 | X31: 10 | Y31: 0 | Z31: 0 | AA31: 0 | AB31: 61160.02 | AC31: 46267 | AD31: SWEJ7U8N6EVPUST | AE31: UI2SB4WQDX | AI31: SasaPay | AJ31: ThirdPartyBillPayment | AK31: 4106574 | AM31: Safaricom | AN31: W13846034 | AO31: W13846034 | AP31: 46267.512 | AQ31: Not Reversed | AR31: user_app | AS31: SUCCESS | AT31: SP00000 | AU31: Transaction completed successfully
A32: UI2SB4WQHH | B32: 02-09-2026 12:27:49 | C32: 02-09-2026 12:27:49 | D32: Business Pay Bill via API to 639498 - GDC SACCO SOCIETY LTD Acc. 10975802 | E32: Completed | G32: -1500 | H32: 28106496 | I32: true | J32: Business Pay Bill via API | K32: 639498 - GDC SACCO SOCIETY LTD | M32: 10975802 | P32: 9235 | Q32: Wimssy | R32: Till | S32: Organisation | T32: Transaction Out | U32: 1500 | V32: =G32+U32 -> 0 | W32: 0 | X32: 25 | Y32: 0 | Z32: 1 | AA32: 0 | AB32: 158004.8 | AC32: 46267 | AD32: SWEJ7U8N6TUK4W6 | AE32: UI2SB4WQHH | AH32: GDC SACCO SOCIETY LTD | AI32: SasaPay | AJ32: ThirdPartyBillPayment | AK32: 639498 | AL32: GDC SACCO SOCIETY LTD | AM32: Safaricom | AN32: W13846196 | AO32: ST0FAxhf7QzUIJPjvRkd | AP32: 46267.519 | AQ32: Not Reversed | AR32: api | AS32: SUCCESS | AT32: SP00000 | AU32: Transaction completed successfully
A33: UI2SB4WQIS | B33: 02-09-2026 12:32:26 | C33: 02-09-2026 12:32:26 | D33: Business Buy Goods at 113322 - SCOOBY ENTREPRISES LIMITED via API REF Bill Payment 1391815 to 113522 | E33: Completed | G33: -15300 | H33: 28006618 | I33: true | J33: Business Buy Goods via API | K33: 113322 - SCOOBY ENTREPRISES LIMITED | P33: 1391815 | Q33: MORINE ONGERI | R33: Limited Personal Wallet | T33: Transaction Out | U33: 15300 | V33: =G33+U33 -> 0 | W33: 0 | X33: 15 | Y33: 18 | Z33: 0 | AA33: 0 | AB33: 49549.18 | AC33: 46267 | AD33: SWEJ7U8N61QWISS | AE33: UI2SB4WQIS | AI33: SasaPay | AJ33: ThirdPartyBillPayment | AK33: 1391815 | AM33: Safaricom | AN33: W13846311 | AO33: GAWOCJ4B | AP33: 46267.522 | AQ33: Not Reversed | AS33: SUCCESS | AT33: SP00000 | AU33: Transaction completed successfully
A34: UI2SB4WQSQ | B34: 02-09-2026 10:00:14 | C34: 02-09-2026 10:00:14 | D34: Business Pay Bill via API to 4131085 - Pharmaplus Pharmaceuticals_23 Acc. n | E34: Completed | G34: -20 | H34: 28502165 | I34: true | J34: Business Pay Bill via API | K34: 4131085 - Pharmaplus Pharmaceuticals_23 | M34: n | O34: 756756 | P34: 254795093834 | Q34: Victor Omondi | R34: Limited Personal Wallet | T34: Transaction Out | U34: 20 | V34: =G34+U34 -> 0 | W34: 0 | X34: 0 | Y34: 0 | Z34: 0 | AA34: 0 | AB34: 56 | AC34: 46267 | AD34: SWEJ7U8NWDUY7OU | AE34: UI2SB4WQSQ | AH34: Pharmaplus Pharmaceuticals_23 | AI34: SasaPay | AJ34: ThirdPartyBillPayment | AK34: 4131085 | AL34: Pharmaplus Pharmaceuticals_23 | AM34: Safaricom | AN34: W13844095 | AO34: n | AP34: 46267.417 | AQ34: Not Reversed | AR34: user_app | AS34: SUCCESS | AT34: SP00000 | AU34: Transaction completed successfully
A35: UI2SB4WRFJ | B35: 02-09-2026 11:19:29 | C35: 02-09-2026 11:19:28 | D35: Business Pay Bill via API to 4107991 - HAWKERS PRIDE ENTERPRISES LIMITED Acc. 3 | E35: Completed | G35: -3720 | H35: 28419913 | I35: true | J35: Business Pay Bill via API | K35: 4107991 - HAWKERS PRIDE ENTERPRISES LIMITED | M35: 3 | O35: 756756 | P35: 358222 | Q35: Dunwell - TUMAINI SHOP | R35: Matatu | T35: Transaction Out | U35: 3720 | V35: =G35+U35 -> 0 | W35: 0 | X35: 49 | Y35: 0 | Z35: 0 | AA35: 0 | AB35: 850.22 | AC35: 46267 | AD35: SWEJ7U8N1UWPKWF | AE35: UI2SB4WRFJ | AH35: HAWKERS PRIDE ENTERPRISES LIMITED | AI35: SasaPay | AJ35: ThirdPartyBillPayment | AK35: 4107991 | AL35: HAWKERS PRIDE ENTERPRISES LIMITED | AM35: Safaricom | AN35: W13845063 | AO35: 3 | AP35: 46267.472 | AQ35: Not Reversed | AR35: user_app | AS35: SUCCESS | AT35: SP00000 | AU35: Transaction completed successfully
A36: UI2SB4WS0S | B36: 02-09-2026 12:27:48 | C36: 02-09-2026 12:27:47 | D36: Business Pay Bill via API to 639498 - GDC SACCO SOCIETY LTD Acc. 21442179 | E36: Completed | G36: -7408 | H36: 28131347 | I36: true | J36: Business Pay Bill via API | K36: 639498 - GDC SACCO SOCIETY LTD | M36: 21442179 | P36: 9235 | Q36: Wimssy | R36: Till | S36: Organisation | T36: Transaction Out | U36: 7408 | V36: =G36+U36 -> 0 | W36: 0 | X36: 57 | Y36: 0 | Z36: 1 | AA36: 0 | AB36: 188066.8 | AC36: 46267 | AD36: SWEJ7U8N6TT24GB | AE36: UI2SB4WS0S | AH36: GDC SACCO SOCIETY LTD | AI36: SasaPay | AJ36: ThirdPartyBillPayment | AK36: 639498 | AL36: GDC SACCO SOCIETY LTD | AM36: Safaricom | AN36: W13846191 | AO36: Bov4xnQYTVKJpZ9cI0lG | AP36: 46267.519 | AQ36: Not Reversed | AR36: api | AS36: SUCCESS | AT36: SP00000 | AU36: Transaction completed successfully
A37: UI2SB4WSPF | B37: 02-09-2026 11:00:44 | C37: 02-09-2026 11:00:44 | D37: Business Buy Goods at 7752793 - IBRAHIM FARMERS CHOICE STOCKISTS via API REF Bill Payment 276585 to 5775191 | E37: Completed | G37: -8120 | H37: 28444418 | I37: true | J37: Business Buy Goods via API | K37: 7752793 - IBRAHIM FARMERS CHOICE STOCKISTS | P37: 276585 | Q37: HEAVENLY WINGS FOODS LIMITED | R37: Till | S37: Organisation | T37: Transaction Out | U37: 8120 | V37: =G37+U37 -> 0 | W37: 0 | X37: 15 | Y37: 0 | Z37: 1 | AA37: 0 | AB37: 13769.36 | AC37: 46267 | AD37: SWEJ7U8N0ZQK5EZ | AE37: UI2SB4WSPF | AI37: SasaPay | AJ37: ThirdPartyBillPayment | AK37: 5775191 | AM37: Safaricom | AN37: W13844860 | AO37: Purchase of sausages, bacon | AP37: 46267.458 | AQ37: Not Reversed | AS37: SUCCESS | AT37: SP00000 | AU37: Transaction completed successfully
A38: UI2SB4WSYZ | B38: 02-09-2026 11:34:38 | C38: 02-09-2026 11:34:38 | D38: Business Pay Bill via API to 583674 - GURU NANAK RAMGARHIA SIKH HOSPITAL Acc. sarah | E38: Completed | G38: -3860 | H38: 28416014 | I38: true | J38: Business Pay Bill via API | K38: 583674 - GURU NANAK RAMGARHIA SIKH HOSPITAL | M38: sarah | P38: 1003020 | Q38: Stephen - Viewtech Afya | R38: Till-CustomerOption | T38: Transaction Out | U38: 3860 | V38: =G38+U38 -> 0 | W38: 0 | X38: 49 | Y38: 38.6 | Z38: 0 | AA38: 0 | AB38: 41918.93 | AC38: 46267 | AD38: SWEJ7U8N2JVF3NG | AE38: UI2SB4WSYZ | AH38: GURU NANAK RAMGARHIA SIKH HOSPITAL | AI38: SasaPay | AJ38: ThirdPartyBillPayment | AK38: 1003020 | AL38: GURU NANAK RAMGARHIA SIKH HOSPITAL | AM38: Safaricom | AN38: W13845310 | AO38: MF166661 | AP38: 46267.482 | AQ38: Not Reversed | AS38: SUCCESS | AT38: SP00000 | AU38: Transaction completed successfully
